Workbook

Sheet municipios datos
A1: codigo_postal | B1: municipio_id | C1: codigo_unidad_poblacional | D1: entidad_singular_nombre | E1: nucleo_nombre | F1: Latitud | G1: Longitud | H1: CPRO | I1: CRPO NORM | J1: PROVINCIA | K1: COMUNIDAD
A2: 1001 | B2: 1059 | C2: 63501 | D2: Vitoria-Gasteiz | E2: Vitoria-Gasteiz | F2: 42.848539 | G2: -2.6722992 | H2: =LEFT(A2,LEN(A2)-3) -> 1 | I2: =TEXT(H2,"00") -> 01 | J2: =VLOOKUP(I2,prov!$B$2:$C$53,2,TRUE) -> Araba/Álava | K2: =VLOOKUP(J2,prov!$C:$F,4,FALSE) -> País Vasco
A3: 1002 | B3: 1059 | C3: 63501 | D3: Vitoria-Gasteiz | E3: Vitoria-Gasteiz | F3: 42.853755 | G3: -2.6573986 | H3: =LEFT(A3,LEN(A3)-3) -> 1 | I3: =TEXT(H3,"00") -> 01 | J3: =VLOOKUP(I3,prov!$B$2:$C$53,2,TRUE) -> Araba/Álava | K3: =VLOOKUP(J3,prov!$C:$F,4,FALSE) -> País Vasco
A4: 1003 | B4: 1059 | C4: 63501 | D4: Vitoria-Gasteiz | E4: Vitoria-Gasteiz | F4: 42.845374 | G4: -2.6511914 | H4: =LEFT(A4,LEN(A4)-3) -> 1 | I4: =TEXT(H4,"00") -> 01 | J4: =VLOOKUP(I4,prov!$B$2:$C$53,2,TRUE) -> Araba/Álava | K4: =VLOOKUP(J4,prov!$C:$F,4,FALSE) -> País Vasco
A5: 1004 | B5: 1059 | C5: 63501 | D5: Vitoria-Gasteiz | E5: Vitoria-Gasteiz | F5: 42.844406 | G5: -2.6667109 | H5: =LEFT(A5,LEN(A5)-3) -> 1 | I5: =TEXT(H5,"00") -> 01 | J5: =VLOOKUP(I5,prov!$B$2:$C$53,2,TRUE) -> Araba/Álava | K5: =VLOOKUP(J5,prov!$C:$F,4,FALSE) -> País Vasco
A6: 1005 | B6: 1059 | C6: 63501 | D6: Vitoria-Gasteiz | E6: Vitoria-Gasteiz | F6: 42.843667 | G6: -2.6722992 | H6: =LEFT(A6,LEN(A6)-3) -> 1 | I6: =TEXT(H6,"00") -> 01 | J6: =VLOOKUP(I6,prov!$B$2:$C$53,2,TRUE) -> Araba/Álava | K6: =VLOOKUP(J6,prov!$C:$F,4,FALSE) -> País Vasco
A7: 1006 | B7: 1059 | C7: 63501 | D7: Vitoria-Gasteiz | E7: Vitoria-Gasteiz | F7: 42.835516 | G7: -2.6561571 | H7: =LEFT(A7,LEN(A7)-3) -> 1 | I7: =TEXT(H7,"00") -> 01 | J7: =VLOOKUP(I7,prov!$B$2:$C$53,2,TRUE) -> Araba/Álava | K7: =VLOOKUP(J7,prov!$C:$F,4,FALSE) -> País Vasco
A8: 1007 | B8: 1059 | C8: 13601 | D8: Armentia | E8: Armentia | F8: 42.834706 | G8: -2.6909317 | H8: =LEFT(A8,LEN(A8)-3) -> 1 | I8: =TEXT(H8,"00") -> 01 | J8: =VLOOKUP(I8,prov!$B$2:$C$53,2,TRUE) -> Araba/Álava | K8: =VLOOKUP(J8,prov!$C:$F,4,FALSE) -> País Vasco
A9: 1008 | B9: 1059 | C9: 63501 | D9: Vitoria-Gasteiz | E9: Vitoria-Gasteiz | F9: 42.848249 | G9: -2.6847201 | H9: =LEFT(A9,LEN(A9)-3) -> 1 | I9: =TEXT(H9,"00") -> 01 | J9: =VLOOKUP(I9,prov!$B$2:$C$53,2,TRUE) -> Araba/Álava | K9: =VLOOKUP(J9,prov!$C:$F,4,FALSE) -> País Vasco
A10: 1009 | B10: 1059 | C10: 63501 | D10: Vitoria-Gasteiz | E10: Vitoria-Gasteiz | F10: 42.854309 | G10: -2.6859623 | H10: =LEFT(A10,LEN(A10)-3) -> 1 | I10: =TEXT(H10,"00") -> 01 | J10: =VLOOKUP(I10,prov!$B$2:$C$53,2,TRUE) -> Araba/Álava | K10: =VLOOKUP(J10,prov!$C:$F,4,FALSE) -> País Vasco
A11: 1010 | B11: 1059 | C11: 3801 | D11: Ehari/Ali | E11: Ehari/Ali | F11: 42.856336 | G11: -2.7033575 | H11: =LEFT(A11,LEN(A11)-3) -> 1 | I11: =TEXT(H11,"00") -> 01 | J11: =VLOOKUP(I11,prov!$B$2:$C$53,2,TRUE) -> Araba/Álava | K11: =VLOOKUP(J11,prov!$C:$F,4,FALSE) -> País Vasco
A12: 1012 | B12: 1028 | C12: 2201 | D12: Salinillas de Buradon/Gat | E12: Salinillas de Buradon/Gat | F12: 42.854541 | G12: -2.6760251 | H12: =LEFT(A12,LEN(A12)-3) -> 1 | I12: =TEXT(H12,"00") -> 01 | J12: =VLOOKUP(I12,prov!$B$2:$C$53,2,TRUE) -> Araba/Álava | K12: =VLOOKUP(J12,prov!$C:$F,4,FALSE) -> País Vasco
A13: 1013 | B13: 1059 | C13: 1701 | D13: Abetxuko | E13: Abetxuko | F13: 42.867005 | G13: -2.6636066 | H13: =LEFT(A13,LEN(A13)-3) -> 1 | I13: =TEXT(H13,"00") -> 01 | J13: =VLOOKUP(I13,prov!$B$2:$C$53,2,TRUE) -> Araba/Álava | K13: =VLOOKUP(J13,prov!$C:$F,4,FALSE) -> País Vasco
... A917: 6500 | B917: 6123 | C917: 1799 | D917: Dehesa Mayorga | E917: Dehesa Mayorga | F917: 39.339073 | G917: -6.9853474 | H917: =LEFT(A917,LEN(A917)-3) -> 6 | I917: =TEXT(H917,"00") -> 06 | J917: =VLOOKUP(I917,prov!$B$2:$C$53,2,TRUE) -> Badajoz | K917: =VLOOKUP(J917,prov!$C:$F,4,FALSE) -> Extremadura
A918: 6501 | B918: 6006 | C918: 5699 | D918: Tejarejo | E918: Tejarejo | H918: =LEFT(A918,LEN(A918)-3) -> 6 | I918: =TEXT(H918,"00") -> 06 | J918: =VLOOKUP(I918,prov!$B$2:$C$53,2,TRUE) -> Badajoz | K918: =VLOOKUP(J918,prov!$C:$F,4,FALSE) -> Extremadura
A919: 6510 | B919: 6006 | C919: 1701 | D919: Alburquerque | E919: Alburquerque | F919: 39.23703 | G919: -6.9638624 | H919: =LEFT(A919,LEN(A919)-3) -> 6 | I919: =TEXT(H919,"00") -> 06 | J919: =VLOOKUP(I919,prov!$B$2:$C$53,2,TRUE) -> Badajoz | K919: =VLOOKUP(J919,prov!$C:$F,4,FALSE) -> Extremadura
A920: 6518 | B920: 6037 | C920: 1701 | D920: Bacoco | E920: Bacoco | F920: 39.233628 | G920: -7.1898025 | H920: =LEFT(A920,LEN(A920)-3) -> 6 | I920: =TEXT(H920,"00") -> 06 | J920: =VLOOKUP(I920,prov!$B$2:$C$53,2,TRUE) -> Badajoz | K920: =VLOOKUP(J920,prov!$C:$F,4,FALSE) -> Extremadura
A921: 6519 | B921: 6006 | C921: 2299 | D921: Benavente | E921: Benavente | F921: 39.19755 | G921: -7.1036396 | H921: =LEFT(A921,LEN(A921)-3) -> 6 | I921: =TEXT(H921,"00") -> 06 | J921: =VLOOKUP(I921,prov!$B$2:$C$53,2,TRUE) -> Badajoz | K921: =VLOOKUP(J921,prov!$C:$F,4,FALSE) -> Extremadura
A922: 6600 | B922: 6023 | C922: 1701 | D922: Almorchon | E922: Almorchon | F922: 38.827402 | G922: -5.2684437 | H922: =LEFT(A922,LEN(A922)-3) -> 6 | I922: =TEXT(H922,"00") -> 06 | J922: =VLOOKUP(I922,prov!$B$2:$C$53,2,TRUE) -> Badajoz | K922: =VLOOKUP(J922,prov!$C:$F,4,FALSE) -> Extremadura
A923: 6610 | B923: 6100 | C923: 1701 | D923: Peñalsordo | E923: Peñalsordo | F923: 38.843862 | G923: -5.1327829 | H923: =LEFT(A923,LEN(A923)-3) -> 6 | I923: =TEXT(H923,"00") -> 06 | J923: =VLOOKUP(I923,prov!$B$2:$C$53,2,TRUE) -> Badajoz | K923: =VLOOKUP(J923,prov!$C:$F,4,FALSE) -> Extremadura
A924: 6611 | B924: 6161 | C924: 1701 | D924: Zarza-Capilla | E924: Zarza-Capilla | F924: 38.769448 | G924: -5.1640605 | H924: =LEFT(A924,LEN(A924)-3) -> 6 | I924: =TEXT(H924,"00") -> 06 | J924: =VLOOKUP(I924,prov!$B$2:$C$53,2,TRUE) -> Badajoz | K924: =VLOOKUP(J924,prov!$C:$F,4,FALSE) -> Extremadura
A925: 6612 | B925: 6030 | C925: 1701 | D925: Capilla | E925: Capilla | F925: 38.774896 | G925: -5.0390536 | H925: =LEFT(A925,LEN(A925)-3) -> 6 | I925: =TEXT(H925,"00") -> 06 | J925: =VLOOKUP(I925,prov!$B$2:$C$53,2,TRUE) -> Badajoz | K925: =VLOOKUP(J925,prov!$C:$F,4,FALSE) -> Extremadura
A926: 6613 | B926: 6018 | C926: 2201 | D926: Helechal | E926: Helechal | F926: 38.666501 | G926: -5.3625516 | H926: =LEFT(A926,LEN(A926)-3) -> 6 | I926: =TEXT(H926,"00") -> 06 | J926: =VLOOKUP(I926,prov!$B$2:$C$53,2,TRUE) -> Badajoz | K926: =VLOOKUP(J926,prov!$C:$F,4,FALSE) -> Extremadura
A927: 6614 | B927: 6023 | C927: 1701 | D927: Almorchon | E927: Almorchon | F927: 38.680284 | G927: -5.2893433 | H927: =LEFT(A927,LEN(A927)-3) -> 6 | I927: =TEXT(H927,"00") -> 06 | J927: =VLOOKUP(I927,prov!$B$2:$C$53,2,TRUE) -> Badajoz | K927: =VLOOKUP(J927,prov!$C:$F,4,FALSE) -> Extremadura
A928: 6615 | B928: 6018 | C928: 3801 | D928: Nava (La) | E928: Nava (La) | F928: 38.68548 | G928: -5.4044268 | H928: =LEFT(A928,LEN(A928)-3) -> 6 | I928: =TEXT(H928,"00") -> 06 | J928: =VLOOKUP(I928,prov!$B$2:$C$53,2,TRUE) -> Badajoz | K928: =VLOOKUP(J928,prov!$C:$F,4,FALSE) -> Extremadura
A929: 6620 | B929: 6048 | C929: 1701 | D929: Esparragosa de Lares | E929: Esparragosa de Lares | F929: 38.968487 | G929: -5.3730176 | H929: =LEFT(A929,LEN(A929)-3) -> 6 | I929: =TEXT(H929,"00") -> 06 | J929: =VLOOKUP(I929,prov!$B$2:$C$53,2,TRUE) -> Badajoz | K929: =VLOOKUP(J929,prov!$C:$F,4,FALSE) -> Extremadura
A930: 6630 | B930: 6102 | C930: 1701 | D930: Puebla de Alcocer | E930: Puebla de Alcocer | F930: 39.051676 | G930: -5.3730176 | H930: =LEFT(A930,LEN(A930)-3) -> 6 | I930: =TEXT(H930,"00") -> 06 | J930: =VLOOKUP(I930,prov!$B$2:$C$53,2,TRUE) -> Badajoz | K930: =VLOOKUP(J930,prov!$C:$F,4,FALSE) -> Extremadura
... A1273: 8256 | B1273: 8002 | C1273: 1701 | D1273: Aguilar de Segarra | E1273: Aguilar de Segarra | F1273: 41.729119 | G1273: 1.6710834 | H1273: =LEFT(A1273,LEN(A1273)-3) -> 8 | I1273: =TEXT(H1273,"00") -> 08 | J1273: =VLOOKUP(I1273,prov!$B$2:$C$53,2,TRUE) -> Barcelona | K1273: =VLOOKUP(J1273,prov!$C:$F,4,FALSE) -> Cataluña
A1274: 8257 | B1274: 8246 | C1274: 1701 | D1274: Santa Eugènia de Berga | E1274: Santa Eugènia de Berga | H1274: =LEFT(A1274,LEN(A1274)-3) -> 8 | I1274: =TEXT(H1274,"00") -> 08 | J1274: =VLOOKUP(I1274,prov!$B$2:$C$53,2,TRUE) -> Barcelona | K1274: =VLOOKUP(J1274,prov!$C:$F,4,FALSE) -> Cataluña
A1275: 8259 | B1275: 8084 | C1275: 1701 | D1275: Camps | E1275: Camps | F1275: 41.7577 | G1275: 1.7246856 | H1275: =LEFT(A1275,LEN(A1275)-3) -> 8 | I1275: =TEXT(H1275,"00") -> 08 | J1275: =VLOOKUP(I1275,prov!$B$2:$C$53,2,TRUE) -> Barcelona | K1275: =VLOOKUP(J1275,prov!$C:$F,4,FALSE) -> Cataluña
A1276: 8260 | B1276: 8274 | C1276: 1701 | D1276: Súria | E1276: Súria | F1276: 41.836651 | G1276: 1.7636181 | H1276: =LEFT(A1276,LEN(A1276)-3) -> 8 | I1276: =TEXT(H1276,"00") -> 08 | J1276: =VLOOKUP(I1276,prov!$B$2:$C$53,2,TRUE) -> Barcelona | K1276: =VLOOKUP(J1276,prov!$C:$F,4,FALSE) -> Cataluña
A1277: 8261 | B1277: 8047 | C1277: 2201 | D1277: Cardona | E1277: Cardona | F1277: 41.897677 | G1277: 1.6663523 | H1277: =LEFT(A1277,LEN(A1277)-3) -> 8 | I1277: =TEXT(H1277,"00") -> 08 | J1277: =VLOOKUP(I1277,prov!$B$2:$C$53,2,TRUE) -> Barcelona | K1277: =VLOOKUP(J1277,prov!$C:$F,4,FALSE) -> Cataluña
A1278: 8262 | B1278: 8038 | C1278: 1701 | D1278: Antius | E1278: Antius | F1278: 41.796596 | G1278: 1.7830973 | H1278: =LEFT(A1278,LEN(A1278)-3) -> 8 | I1278: =TEXT(H1278,"00") -> 08 | J1278: =VLOOKUP(I1278,prov!$B$2:$C$53,2,TRUE) -> Barcelona | K1278: =VLOOKUP(J1278,prov!$C:$F,4,FALSE) -> Cataluña
A1279: 8263 | B1279: 8229 | C1279: 1799 | D1279: Castelltallat | E1279: Castelltallat | F1279: 41.818224 | G1279: 1.6663523 | H1279: =LEFT(A1279,LEN(A1279)-3) -> 8 | I1279: =TEXT(H1279,"00") -> 08 | J1279: =VLOOKUP(I1279,prov!$B$2:$C$53,2,TRUE) -> Barcelona | K1279: =VLOOKUP(J1279,prov!$C:$F,4,FALSE) -> Cataluña
A1280: 8269 | B1280: 8141 | C1280: 1701 | D1280: Castelladral | E1280: Castelladral | F1280: 41.857396 | G1280: 1.7052325 | H1280: =LEFT(A1280,LEN(A1280)-3) -> 8 | I1280: =TEXT(H1280,"00") -> 08 | J1280: =VLOOKUP(I1280,prov!$B$2:$C$53,2,TRUE) -> Barcelona | K1280: =VLOOKUP(J1280,prov!$C:$F,4,FALSE) -> Cataluña
A1281: 8270 | B1281: 8140 | C1281: 1701 | D1281: Navarcles | E1281: Navarcles | F1281: 41.749724 | G1281: 1.9148091 | H1281: =LEFT(A1281,LEN(A1281)-3) -> 8 | I1281: =TEXT(H1281,"00") -> 08 | J1281: =VLOOKUP(I1281,prov!$B$2:$C$53,2,TRUE) -> Barcelona | K1281: =VLOOKUP(J1281,prov!$C:$F,4,FALSE) -> Cataluña
A1282: 8271 | B1282: 8010 | C1282: 1701 | D1282: Artés | E1282: Artés | F1282: 41.798798 | G1282: 1.9539106 | H1282: =LEFT(A1282,LEN(A1282)-3) -> 8 | I1282: =TEXT(H1282,"00") -> 08 | J1282: =VLOOKUP(I1282,prov!$B$2:$C$53,2,TRUE) -> Barcelona | K1282: =VLOOKUP(J1282,prov!$C:$F,4,FALSE) -> Cataluña
A1283: 8272 | B1283: 8213 | C1283: 1701 | D1283: Rosaleda de Bages (La) | E1283: Rosaleda de Bages (La) | F1283: 41.755262 | G1283: 1.8806237 | H1283: =LEFT(A1283,LEN(A1283)-3) -> 8 | I1283: =TEXT(H1283,"00") -> 08 | J1283: =VLOOKUP(I1283,prov!$B$2:$C$53,2,TRUE) -> Barcelona | K1283: =VLOOKUP(J1283,prov!$C:$F,4,FALSE) -> Cataluña
A1284: 8273 | B1284: 8258 | C1284: 1799 | D1284: Raval de la Rovirola (El) | E1284: Raval de la Rovirola (El) | F1284: 41.871518 | G1284: 2.0567163 | H1284: =LEFT(A1284,LEN(A1284)-3) -> 8 | I1284: =TEXT(H1284,"00") -> 08 | J1284: =VLOOKUP(I1284,prov!$B$2:$C$53,2,TRUE) -> Barcelona | K1284: =VLOOKUP(J1284,prov!$C:$F,4,FALSE) -> Cataluña
A1285: 8274 | B1285: 8212 | C1285: 1701 | D1285: Sant Feliu Sasserra | E1285: Sant Feliu Sasserra | F1285: 41.936959 | G1285: 2.002836 | H1285: =LEFT(A1285,LEN(A1285)-3) -> 8 | I1285: =TEXT(H1285,"00") -> 08 | J1285: =VLOOKUP(I1285,prov!$B$2:$C$53,2,TRUE) -> Barcelona | K1285: =VLOOKUP(J1285,prov!$C:$F,4,FALSE) -> Cataluña
...

Sheet prov
A1: CPRO | B1: CRPO NORM | C1: Provincia | D1: CODAUTO | E1: CODAUTO NORM | F1: Comunidad Autónoma
A2: 1 | B2: =TEXT(A2,"00") -> 01 | C2: Araba/Álava | D2: 16 | E2: =TEXT(D2,"00") -> 16 | F2: País Vasco
A3: 2 | B3: =TEXT(A3,"00") -> 02 | C3: Albacete | D3: 8 | E3: =TEXT(D3,"00") -> 08 | F3: Castilla-La Mancha
A4: 3 | B4: =TEXT(A4,"00") -> 03 | C4: Alicante/Alacant | D4: 10 | E4: =TEXT(D4,"00") -> 10 | F4: Comunitat Valenciana
A5: 4 | B5: =TEXT(A5,"00") -> 04 | C5: Almería | D5: 1 | E5: =TEXT(D5,"00") -> 01 | F5: Andalucía
A6: 5 | B6: =TEXT(A6,"00") -> 05 | C6: Ávila | D6: 7 | E6: =TEXT(D6,"00") -> 07 | F6: Castilla y León
A7: 6 | B7: =TEXT(A7,"00") -> 06 | C7: Badajoz | D7: 11 | E7: =TEXT(D7,"00") -> 11 | F7: Extremadura
A8: 7 | B8: =TEXT(A8,"00") -> 07 | C8: Balears, Illes | D8: 4 | E8: =TEXT(D8,"00") -> 04 | F8: Balears, Illes
A9: 8 | B9: =TEXT(A9,"00") -> 08 | C9: Barcelona | D9: 9 | E9: =TEXT(D9,"00") -> 09 | F9: Cataluña
A10: 9 | B10: =TEXT(A10,"00") -> 09 | C10: Burgos | D10: 7 | E10: =TEXT(D10,"00") -> 07 | F10: Castilla y León
A11: 10 | B11: =TEXT(A11,"00") -> 10 | C11: Cáceres | D11: 11 | E11: =TEXT(D11,"00") -> 11 | F11: Extremadura
A12: 11 | B12: =TEXT(A12,"00") -> 11 | C12: Cádiz | D12: 1 | E12: =TEXT(D12,"00") -> 01 | F12: Andalucía
A13: 12 | B13: =TEXT(A13,"00") -> 12 | C13: Castellón/Castelló | D13: 10 | E13: =TEXT(D13,"00") -> 10 | F13: Comunitat Valenciana
... A53: 52 | B53: =TEXT(A53,"00") -> 52 | C53: Melilla | D53: 19 | E53: =TEXT(D53,"00") -> 19 | F53: Melilla
